Workbook

Sheet Search
A1: Kushal Timbers — Barcode Search
A3: Type barcode here | D3: Part of a barcode works too — type 4729 to see every log containing 4729.
A5: =IF($B$3="","Type a barcode in the yellow box above.",IF(MAX(Data!$K$2:$K$5001)=0,"No log found with that barcode.",MAX(Data!$K$2:$K$5001)&" log(s) found:")) -> Type a barcode in the yellow box above.
A7: Barcode | B7: Wood Type | C7: Size | D7: CFT | E7: Lot No. | F7: Date In | G7: Supplier | H7: Rate (Rs)
A8: =IFERROR(INDEX(Data!A$2:A$5001,MATCH(1,Data!$K$2:$K$5001,0)),"") | B8: =IFERROR(INDEX(Data!B$2:B$5001,MATCH(1,Data!$K$2:$K$5001,0)),"") | C8: =IFERROR(INDEX(Data!C$2:C$5001,MATCH(1,Data!$K$2:$K$5001,0)),"") | D8: =IFERROR(INDEX(Data!D$2:D$5001,MATCH(1,Data!$K$2:$K$5001,0)),"") | E8: =IFERROR(INDEX(Data!E$2:E$5001,MATCH(1,Data!$K$2:$K$5001,0)),"") | F8: =IFERROR(INDEX(Data!F$2:F$5001,MATCH(1,Data!$K$2:$K$5001,0)),"") | G8: =IFERROR(INDEX(Data!G$2:G$5001,MATCH(1,Data!$K$2:$K$5001,0)),"") | H8: =IFERROR(INDEX(Data!H$2:H$5001,MATCH(1,Data!$K$2:$K$5001,0)),"")
A9: =IFERROR(INDEX(Data!A$2:A$5001,MATCH(2,Data!$K$2:$K$5001,0)),"") | B9: =IFERROR(INDEX(Data!B$2:B$5001,MATCH(2,Data!$K$2:$K$5001,0)),"") | C9: =IFERROR(INDEX(Data!C$2:C$5001,MATCH(2,Data!$K$2:$K$5001,0)),"") | D9: =IFERROR(INDEX(Data!D$2:D$5001,MATCH(2,Data!$K$2:$K$5001,0)),"") | E9: =IFERROR(INDEX(Data!E$2:E$5001,MATCH(2,Data!$K$2:$K$5001,0)),"") | F9: =IFERROR(INDEX(Data!F$2:F$5001,MATCH(2,Data!$K$2:$K$5001,0)),"") | G9: =IFERROR(INDEX(Data!G$2:G$5001,MATCH(2,Data!$K$2:$K$5001,0)),"") | H9: =IFERROR(INDEX(Data!H$2:H$5001,MATCH(2,Data!$K$2:$K$5001,0)),"")
A10: =IFERROR(INDEX(Data!A$2:A$5001,MATCH(3,Data!$K$2:$K$5001,0)),"") | B10: =IFERROR(INDEX(Data!B$2:B$5001,MATCH(3,Data!$K$2:$K$5001,0)),"") | C10: =IFERROR(INDEX(Data!C$2:C$5001,MATCH(3,Data!$K$2:$K$5001,0)),"") | D10: =IFERROR(INDEX(Data!D$2:D$5001,MATCH(3,Data!$K$2:$K$5001,0)),"") | E10: =IFERROR(INDEX(Data!E$2:E$5001,MATCH(3,Data!$K$2:$K$5001,0)),"") | F10: =IFERROR(INDEX(Data!F$2:F$5001,MATCH(3,Data!$K$2:$K$5001,0)),"") | G10: =IFERROR(INDEX(Data!G$2:G$5001,MATCH(3,Data!$K$2:$K$5001,0)),"") | H10: =IFERROR(INDEX(Data!H$2:H$5001,MATCH(3,Data!$K$2:$K$5001,0)),"")
A11: =IFERROR(INDEX(Data!A$2:A$5001,MATCH(4,Data!$K$2:$K$5001,0)),"") | B11: =IFERROR(INDEX(Data!B$2:B$5001,MATCH(4,Data!$K$2:$K$5001,0)),"") | C11: =IFERROR(INDEX(Data!C$2:C$5001,MATCH(4,Data!$K$2:$K$5001,0)),"") | D11: =IFERROR(INDEX(Data!D$2:D$5001,MATCH(4,Data!$K$2:$K$5001,0)),"") | E11: =IFERROR(INDEX(Data!E$2:E$5001,MATCH(4,Data!$K$2:$K$5001,0)),"") | F11: =IFERROR(INDEX(Data!F$2:F$5001,MATCH(4,Data!$K$2:$K$5001,0)),"") | G11: =IFERROR(INDEX(Data!G$2:G$5001,MATCH(4,Data!$K$2:$K$5001,0)),"") | H11: =IFERROR(INDEX(Data!H$2:H$5001,MATCH(4,Data!$K$2:$K$5001,0)),"")
A12: =IFERROR(INDEX(Data!A$2:A$5001,MATCH(5,Data!$K$2:$K$5001,0)),"") | B12: =IFERROR(INDEX(Data!B$2:B$5001,MATCH(5,Data!$K$2:$K$5001,0)),"") | C12: =IFERROR(INDEX(Data!C$2:C$5001,MATCH(5,Data!$K$2:$K$5001,0)),"") | D12: =IFERROR(INDEX(Data!D$2:D$5001,MATCH(5,Data!$K$2:$K$5001,0)),"") | E12: =IFERROR(INDEX(Data!E$2:E$5001,MATCH(5,Data!$K$2:$K$5001,0)),"") | F12: =IFERROR(INDEX(Data!F$2:F$5001,MATCH(5,Data!$K$2:$K$5001,0)),"") | G12: =IFERROR(INDEX(Data!G$2:G$5001,MATCH(5,Data!$K$2:$K$5001,0)),"") | H12: =IFERROR(INDEX(Data!H$2:H$5001,MATCH(5,Data!$K$2:$K$5001,0)),"")
A13: =IFERROR(INDEX(Data!A$2:A$5001,MATCH(6,Data!$K$2:$K$5001,0)),"") | B13: =IFERROR(INDEX(Data!B$2:B$5001,MATCH(6,Data!$K$2:$K$5001,0)),"") | C13: =IFERROR(INDEX(Data!C$2:C$5001,MATCH(6,Data!$K$2:$K$5001,0)),"") | D13: =IFERROR(INDEX(Data!D$2:D$5001,MATCH(6,Data!$K$2:$K$5001,0)),"") | E13: =IFERROR(INDEX(Data!E$2:E$5001,MATCH(6,Data!$K$2:$K$5001,0)),"") | F13: =IFERROR(INDEX(Data!F$2:F$5001,MATCH(6,Data!$K$2:$K$5001,0)),"") | G13: =IFERROR(INDEX(Data!G$2:G$5001,MATCH(6,Data!$K$2:$K$5001,0)),"") | H13: =IFERROR(INDEX(Data!H$2:H$5001,MATCH(6,Data!$K$2:$K$5001,0)),"")
A14: =IFERROR(INDEX(Data!A$2:A$5001,MATCH(7,Data!$K$2:$K$5001,0)),"") | B14: =IFERROR(INDEX(Data!B$2:B$5001,MATCH(7,Data!$K$2:$K$5001,0)),"") | C14: =IFERROR(INDEX(Data!C$2:C$5001,MATCH(7,Data!$K$2:$K$5001,0)),"") | D14: =IFERROR(INDEX(Data!D$2:D$5001,MATCH(7,Data!$K$2:$K$5001,0)),"") | E14: =IFERROR(INDEX(Data!E$2:E$5001,MATCH(7,Data!$K$2:$K$5001,0)),"") | F14: =IFERROR(INDEX(Data!F$2:F$5001,MATCH(7,Data!$K$2:$K$5001,0)),"") | G14: =IFERROR(INDEX(Data!G$2:G$5001,MATCH(7,Data!$K$2:$K$5001,0)),"") | H14: =IFERROR(INDEX(Data!H$2:H$5001,MATCH(7,Data!$K$2:$K$5001,0)),"")
A15: =IFERROR(INDEX(Data!A$2:A$5001,MATCH(8,Data!$K$2:$K$5001,0)),"") | B15: =IFERROR(INDEX(Data!B$2:B$5001,MATCH(8,Data!$K$2:$K$5001,0)),"") | C15: =IFERROR(INDEX(Data!C$2:C$5001,MATCH(8,Data!$K$2:$K$5001,0)),"") | D15: =IFERROR(INDEX(Data!D$2:D$5001,MATCH(8,Data!$K$2:$K$5001,0)),"") | E15: =IFERROR(INDEX(Data!E$2:E$5001,MATCH(8,Data!$K$2:$K$5001,0)),"") | F15: =IFERROR(INDEX(Data!F$2:F$5001,MATCH(8,Data!$K$2:$K$5001,0)),"") | G15: =IFERROR(INDEX(Data!G$2:G$5001,MATCH(8,Data!$K$2:$K$5001,0)),"") | H15: =IFERROR(INDEX(Data!H$2:H$5001,MATCH(8,Data!$K$2:$K$5001,0)),"")
A16: =IFERROR(INDEX(Data!A$2:A$5001,MATCH(9,Data!$K$2:$K$5001,0)),"") | B16: =IFERROR(INDEX(Data!B$2:B$5001,MATCH(9,Data!$K$2:$K$5001,0)),"") | C16: =IFERROR(INDEX(Data!C$2:C$5001,MATCH(9,Data!$K$2:$K$5001,0)),"") | D16: =IFERROR(INDEX(Data!D$2:D$5001,MATCH(9,Data!$K$2:$K$5001,0)),"") | E16: =IFERROR(INDEX(Data!E$2:E$5001,MATCH(9,Data!$K$2:$K$5001,0)),"") | F16: =IFERROR(INDEX(Data!F$2:F$5001,MATCH(9,Data!$K$2:$K$5001,0)),"") | G16: =IFERROR(INDEX(Data!G$2:G$5001,MATCH(9,Data!$K$2:$K$5001,0)),"") | H16: =IFERROR(INDEX(Data!H$2:H$5001,MATCH(9,Data!$K$2:$K$5001,0)),"")
A17: =IFERROR(INDEX(Data!A$2:A$5001,MATCH(10,Data!$K$2:$K$5001,0)),"") | B17: =IFERROR(INDEX(Data!B$2:B$5001,MATCH(10,Data!$K$2:$K$5001,0)),"") | C17: =IFERROR(INDEX(Data!C$2:C$5001,MATCH(10,Data!$K$2:$K$5001,0)),"") | D17: =IFERROR(INDEX(Data!D$2:D$5001,MATCH(10,Data!$K$2:$K$5001,0)),"") | E17: =IFERROR(INDEX(Data!E$2:E$5001,MATCH(10,Data!$K$2:$K$5001,0)),"") | F17: =IFERROR(INDEX(Data!F$2:F$5001,MATCH(10,Data!$K$2:$K$5001,0)),"") | G17: =IFERROR(INDEX(Data!G$2:G$5001,MATCH(10,Data!$K$2:$K$5001,0)),"") | H17: =IFERROR(INDEX(Data!H$2:H$5001,MATCH(10,Data!$K$2:$K$5001,0)),"")
A18: =IFERROR(INDEX(Data!A$2:A$5001,MATCH(11,Data!$K$2:$K$5001,0)),"") | B18: =IFERROR(INDEX(Data!B$2:B$5001,MATCH(11,Data!$K$2:$K$5001,0)),"") | C18: =IFERROR(INDEX(Data!C$2:C$5001,MATCH(11,Data!$K$2:$K$5001,0)),"") | D18: =IFERROR(INDEX(Data!D$2:D$5001,MATCH(11,Data!$K$2:$K$5001,0)),"") | E18: =IFERROR(INDEX(Data!E$2:E$5001,MATCH(11,Data!$K$2:$K$5001,0)),"") | F18: =IFERROR(INDEX(Data!F$2:F$5001,MATCH(11,Data!$K$2:$K$5001,0)),"") | G18: =IFERROR(INDEX(Data!G$2:G$5001,MATCH(11,Data!$K$2:$K$5001,0)),"") | H18: =IFERROR(INDEX(Data!H$2:H$5001,MATCH(11,Data!$K$2:$K$5001,0)),"")
A19: =IFERROR(INDEX(Data!A$2:A$5001,MATCH(12,Data!$K$2:$K$5001,0)),"") | B19: =IFERROR(INDEX(Data!B$2:B$5001,MATCH(12,Data!$K$2:$K$5001,0)),"") | C19: =IFERROR(INDEX(Data!C$2:C$5001,MATCH(12,Data!$K$2:$K$5001,0)),"") | D19: =IFERROR(INDEX(Data!D$2:D$5001,MATCH(12,Data!$K$2:$K$5001,0)),"") | E19: =IFERROR(INDEX(Data!E$2:E$5001,MATCH(12,Data!$K$2:$K$5001,0)),"") | F19: =IFERROR(INDEX(Data!F$2:F$5001,MATCH(12,Data!$K$2:$K$5001,0)),"") | G19: =IFERROR(INDEX(Data!G$2:G$5001,MATCH(12,Data!$K$2:$K$5001,0)),"") | H19: =IFERROR(INDEX(Data!H$2:H$5001,MATCH(12,Data!$K$2:$K$5001,0)),"")
A20: =IFERROR(INDEX(Data!A$2:A$5001,MATCH(13,Data!$K$2:$K$5001,0)),"") | B20: =IFERROR(INDEX(Data!B$2:B$5001,MATCH(13,Data!$K$2:$K$5001,0)),"") | C20: =IFERROR(INDEX(Data!C$2:C$5001,MATCH(13,Data!$K$2:$K$5001,0)),"") | D20: =IFERROR(INDEX(Data!D$2:D$5001,MATCH(13,Data!$K$2:$K$5001,0)),"") | E20: =IFERROR(INDEX(Data!E$2:E$5001,MATCH(13,Data!$K$2:$K$5001,0)),"") | F20: =IFERROR(INDEX(Data!F$2:F$5001,MATCH(13,Data!$K$2:$K$5001,0)),"") | G20: =IFERROR(INDEX(Data!G$2:G$5001,MATCH(13,Data!$K$2:$K$5001,0)),"") | H20: =IFERROR(INDEX(Data!H$2:H$5001,MATCH(13,Data!$K$2:$K$5001,0)),"")
A21: =IFERROR(INDEX(Data!A$2:A$5001,MATCH(14,Data!$K$2:$K$5001,0)),"") | B21: =IFERROR(INDEX(Data!B$2:B$5001,MATCH(14,Data!$K$2:$K$5001,0)),"") | C21: =IFERROR(INDEX(Data!C$2:C$5001,MATCH(14,Data!$K$2:$K$5001,0)),"") | D21: =IFERROR(INDEX(Data!D$2:D$5001,MATCH(14,Data!$K$2:$K$5001,0)),"") | E21: =IFERROR(INDEX(Data!E$2:E$5001,MATCH(14,Data!$K$2:$K$5001,0)),"") | F21: =IFERROR(INDEX(Data!F$2:F$5001,MATCH(14,Data!$K$2:$K$5001,0)),"") | G21: =IFERROR(INDEX(Data!G$2:G$5001,MATCH(14,Data!$K$2:$K$5001,0)),"") | H21: =IFERROR(INDEX(Data!H$2:H$5001,MATCH(14,Data!$K$2:$K$5001,0)),"")
A22: =IFERROR(INDEX(Data!A$2:A$5001,MATCH(15,Data!$K$2:$K$5001,0)),"") | B22: =IFERROR(INDEX(Data!B$2:B$5001,MATCH(15,Data!$K$2:$K$5001,0)),"") | C22: =IFERROR(INDEX(Data!C$2:C$5001,MATCH(15,Data!$K$2:$K$5001,0)),"") | D22: =IFERROR(INDEX(Data!D$2:D$5001,MATCH(15,Data!$K$2:$K$5001,0)),"") | E22: =IFERROR(INDEX(Data!E$2:E$5001,MATCH(15,Data!$K$2:$K$5001,0)),"") | F22: =IFERROR(INDEX(Data!F$2:F$5001,MATCH(15,Data!$K$2:$K$5001,0)),"") | G22: =IFERROR(INDEX(Data!G$2:G$5001,MATCH(15,Data!$K$2:$K$5001,0)),"") | H22: =IFERROR(INDEX(Data!H$2:H$5001,MATCH(15,Data!$K$2:$K$5001,0)),"")
A23: =IFERROR(INDEX(Data!A$2:A$5001,MATCH(16,Data!$K$2:$K$5001,0)),"") | B23: =IFERROR(INDEX(Data!B$2:B$5001,MATCH(16,Data!$K$2:$K$5001,0)),"") | C23: =IFERROR(INDEX(Data!C$2:C$5001,MATCH(16,Data!$K$2:$K$5001,0)),"") | D23: =IFERROR(INDEX(Data!D$2:D$5001,MATCH(16,Data!$K$2:$K$5001,0)),"") | E23: =IFERROR(INDEX(Data!E$2:E$5001,MATCH(16,Data!$K$2:$K$5001,0)),"") | F23: =IFERROR(INDEX(Data!F$2:F$5001,MATCH(16,Data!$K$2:$K$5001,0)),"") | G23: =IFERROR(INDEX(Data!G$2:G$5001,MATCH(16,Data!$K$2:$K$5001,0)),"") | H23: =IFERROR(INDEX(Data!H$2:H$5001,MATCH(16,Data!$K$2:$K$5001,0)),"")
A24: =IFERROR(INDEX(Data!A$2:A$5001,MATCH(17,Data!$K$2:$K$5001,0)),"") | B24: =IFERROR(INDEX(Data!B$2:B$5001,MATCH(17,Data!$K$2:$K$5001,0)),"") | C24: =IFERROR(INDEX(Data!C$2:C$5001,MATCH(17,Data!$K$2:$K$5001,0)),"") | D24: =IFERROR(INDEX(Data!D$2:D$5001,MATCH(17,Data!$K$2:$K$5001,0)),"") | E24: =IFERROR(INDEX(Data!E$2:E$5001,MATCH(17,Data!$K$2:$K$5001,0)),"") | F24: =IFERROR(INDEX(Data!F$2:F$5001,MATCH(17,Data!$K$2:$K$5001,0)),"") | G24: =IFERROR(INDEX(Data!G$2:G$5001,MATCH(17,Data!$K$2:$K$5001,0)),"") | H24: =IFERROR(INDEX(Data!H$2:H$5001,MATCH(17,Data!$K$2:$K$5001,0)),"")
A25: =IFERROR(INDEX(Data!A$2:A$5001,MATCH(18,Data!$K$2:$K$5001,0)),"") | B25: =IFERROR(INDEX(Data!B$2:B$5001,MATCH(18,Data!$K$2:$K$5001,0)),"") | C25: =IFERROR(INDEX(Data!C$2:C$5001,MATCH(18,Data!$K$2:$K$5001,0)),"") | D25: =IFERROR(INDEX(Data!D$2:D$5001,MATCH(18,Data!$K$2:$K$5001,0)),"") | E25: =IFERROR(INDEX(Data!E$2:E$5001,MATCH(18,Data!$K$2:$K$5001,0)),"") | F25: =IFERROR(INDEX(Data!F$2:F$5001,MATCH(18,Data!$K$2:$K$5001,0)),"") | G25: =IFERROR(INDEX(Data!G$2:G$5001,MATCH(18,Data!$K$2:$K$5001,0)),"") | H25: =IFERROR(INDEX(Data!H$2:H$5001,MATCH(18,Data!$K$2:$K$5001,0)),"")
A26: =IFERROR(INDEX(Data!A$2:A$5001,MATCH(19,Data!$K$2:$K$5001,0)),"") | B26: =IFERROR(INDEX(Data!B$2:B$5001,MATCH(19,Data!$K$2:$K$5001,0)),"") | C26: =IFERROR(INDEX(Data!C$2:C$5001,MATCH(19,Data!$K$2:$K$5001,0)),"") | D26: =IFERROR(INDEX(Data!D$2:D$5001,MATCH(19,Data!$K$2:$K$5001,0)),"") | E26: =IFERROR(INDEX(Data!E$2:E$5001,MATCH(19,Data!$K$2:$K$5001,0)),"") | F26: =IFERROR(INDEX(Data!F$2:F$5001,MATCH(19,Data!$K$2:$K$5001,0)),"") | G26: =IFERROR(INDEX(Data!G$2:G$5001,MATCH(19,Data!$K$2:$K$5001,0)),"") | H26: =IFERROR(INDEX(Data!H$2:H$5001,MATCH(19,Data!$K$2:$K$5001,0)),"")
A27: =IFERROR(INDEX(Data!A$2:A$5001,MATCH(20,Data!$K$2:$K$5001,0)),"") | B27: =IFERROR(INDEX(Data!B$2:B$5001,MATCH(20,Data!$K$2:$K$5001,0)),"") | C27: =IFERROR(INDEX(Data!C$2:C$5001,MATCH(20,Data!$K$2:$K$5001,0)),"") | D27: =IFERROR(INDEX(Data!D$2:D$5001,MATCH(20,Data!$K$2:$K$5001,0)),"") | E27: =IFERROR(INDEX(Data!E$2:E$5001,MATCH(20,Data!$K$2:$K$5001,0)),"") | F27: =IFERROR(INDEX(Data!F$2:F$5001,MATCH(20,Data!$K$2:$K$5001,0)),"") | G27: =IFERROR(INDEX(Data!G$2:G$5001,MATCH(20,Data!$K$2:$K$5001,0)),"") | H27: =IFERROR(INDEX(Data!H$2:H$5001,MATCH(20,Data!$K$2:$K$5001,0)),"")
A28: =IFERROR(INDEX(Data!A$2:A$5001,MATCH(21,Data!$K$2:$K$5001,0)),"") | B28: =IFERROR(INDEX(Data!B$2:B$5001,MATCH(21,Data!$K$2:$K$5001,0)),"") | C28: =IFERROR(INDEX(Data!C$2:C$5001,MATCH(21,Data!$K$2:$K$5001,0)),"") | D28: =IFERROR(INDEX(Data!D$2:D$5001,MATCH(21,Data!$K$2:$K$5001,0)),"") | E28: =IFERROR(INDEX(Data!E$2:E$5001,MATCH(21,Data!$K$2:$K$5001,0)),"") | F28: =IFERROR(INDEX(Data!F$2:F$5001,MATCH(21,Data!$K$2:$K$5001,0)),"") | G28: =IFERROR(INDEX(Data!G$2:G$5001,MATCH(21,Data!$K$2:$K$5001,0)),"") | H28: =IFERROR(INDEX(Data!H$2:H$5001,MATCH(21,Data!$K$2:$K$5001,0)),"")
A29: =IFERROR(INDEX(Data!A$2:A$5001,MATCH(22,Data!$K$2:$K$5001,0)),"") | B29: =IFERROR(INDEX(Data!B$2:B$5001,MATCH(22,Data!$K$2:$K$5001,0)),"") | C29: =IFERROR(INDEX(Data!C$2:C$5001,MATCH(22,Data!$K$2:$K$5001,0)),"") | D29: =IFERROR(INDEX(Data!D$2:D$5001,MATCH(22,Data!$K$2:$K$5001,0)),"") | E29: =IFERROR(INDEX(Data!E$2:E$5001,MATCH(22,Data!$K$2:$K$5001,0)),"") | F29: =IFERROR(INDEX(Data!F$2:F$5001,MATCH(22,Data!$K$2:$K$5001,0)),"") | G29: =IFERROR(INDEX(Data!G$2:G$5001,MATCH(22,Data!$K$2:$K$5001,0)),"") | H29: =IFERROR(INDEX(Data!H$2:H$5001,MATCH(22,Data!$K$2:$K$5001,0)),"")
A30: =IFERROR(INDEX(Data!A$2:A$5001,MATCH(23,Data!$K$2:$K$5001,0)),"") | B30: =IFERROR(INDEX(Data!B$2:B$5001,MATCH(23,Data!$K$2:$K$5001,0)),"") | C30: =IFERROR(INDEX(Data!C$2:C$5001,MATCH(23,Data!$K$2:$K$5001,0)),"") | D30: =IFERROR(INDEX(Data!D$2:D$5001,MATCH(23,Data!$K$2:$K$5001,0)),"") | E30: =IFERROR(INDEX(Data!E$2:E$5001,MATCH(23,Data!$K$2:$K$5001,0)),"") | F30: =IFERROR(INDEX(Data!F$2:F$5001,MATCH(23,Data!$K$2:$K$5001,0)),"") | G30: =IFERROR(INDEX(Data!G$2:G$5001,MATCH(23,Data!$K$2:$K$5001,0)),"") | H30: =IFERROR(INDEX(Data!H$2:H$5001,MATCH(23,Data!$K$2:$K$5001,0)),"")
A31: =IFERROR(INDEX(Data!A$2:A$5001,MATCH(24,Data!$K$2:$K$5001,0)),"") | B31: =IFERROR(INDEX(Data!B$2:B$5001,MATCH(24,Data!$K$2:$K$5001,0)),"") | C31: =IFERROR(INDEX(Data!C$2:C$5001,MATCH(24,Data!$K$2:$K$5001,0)),"") | D31: =IFERROR(INDEX(Data!D$2:D$5001,MATCH(24,Data!$K$2:$K$5001,0)),"") | E31: =IFERROR(INDEX(Data!E$2:E$5001,MATCH(24,Data!$K$2:$K$5001,0)),"") | F31: =IFERROR(INDEX(Data!F$2:F$5001,MATCH(24,Data!$K$2:$K$5001,0)),"") | G31: =IFERROR(INDEX(Data!G$2:G$5001,MATCH(24,Data!$K$2:$K$5001,0)),"") | H31: =IFERROR(INDEX(Data!H$2:H$5001,MATCH(24,Data!$K$2:$K$5001,0)),"")
A32: =IFERROR(INDEX(Data!A$2:A$5001,MATCH(25,Data!$K$2:$K$5001,0)),"") | B32: =IFERROR(INDEX(Data!B$2:B$5001,MATCH(25,Data!$K$2:$K$5001,0)),"") | C32: =IFERROR(INDEX(Data!C$2:C$5001,MATCH(25,Data!$K$2:$K$5001,0)),"") | D32: =IFERROR(INDEX(Data!D$2:D$5001,MATCH(25,Data!$K$2:$K$5001,0)),"") | E32: =IFERROR(INDEX(Data!E$2:E$5001,MATCH(25,Data!$K$2:$K$5001,0)),"") | F32: =IFERROR(INDEX(Data!F$2:F$5001,MATCH(25,Data!$K$2:$K$5001,0)),"") | G32: =IFERROR(INDEX(Data!G$2:G$5001,MATCH(25,Data!$K$2:$K$5001,0)),"") | H32: =IFERROR(INDEX(Data!H$2:H$5001,MATCH(25,Data!$K$2:$K$5001,0)),"")
A33: =IFERROR(INDEX(Data!A$2:A$5001,MATCH(26,Data!$K$2:$K$5001,0)),"") | B33: =IFERROR(INDEX(Data!B$2:B$5001,MATCH(26,Data!$K$2:$K$5001,0)),"") | C33: =IFERROR(INDEX(Data!C$2:C$5001,MATCH(26,Data!$K$2:$K$5001,0)),"") | D33: =IFERROR(INDEX(Data!D$2:D$5001,MATCH(26,Data!$K$2:$K$5001,0)),"") | E33: =IFERROR(INDEX(Data!E$2:E$5001,MATCH(26,Data!$K$2:$K$5001,0)),"") | F33: =IFERROR(INDEX(Data!F$2:F$5001,MATCH(26,Data!$K$2:$K$5001,0)),"") | G33: =IFERROR(INDEX(Data!G$2:G$5001,MATCH(26,Data!$K$2:$K$5001,0)),"") | H33: =IFERROR(INDEX(Data!H$2:H$5001,MATCH(26,Data!$K$2:$K$5001,0)),"")
A34: =IFERROR(INDEX(Data!A$2:A$5001,MATCH(27,Data!$K$2:$K$5001,0)),"") | B34: =IFERROR(INDEX(Data!B$2:B$5001,MATCH(27,Data!$K$2:$K$5001,0)),"") | C34: =IFERROR(INDEX(Data!C$2:C$5001,MATCH(27,Data!$K$2:$K$5001,0)),"") | D34: =IFERROR(INDEX(Data!D$2:D$5001,MATCH(27,Data!$K$2:$K$5001,0)),"") | E34: =IFERROR(INDEX(Data!E$2:E$5001,MATCH(27,Data!$K$2:$K$5001,0)),"") | F34: =IFERROR(INDEX(Data!F$2:F$5001,MATCH(27,Data!$K$2:$K$5001,0)),"") | G34: =IFERROR(INDEX(Data!G$2:G$5001,MATCH(27,Data!$K$2:$K$5001,0)),"") | H34: =IFERROR(INDEX(Data!H$2:H$5001,MATCH(27,Data!$K$2:$K$5001,0)),"")
A35: =IFERROR(INDEX(Data!A$2:A$5001,MATCH(28,Data!$K$2:$K$5001,0)),"") | B35: =IFERROR(INDEX(Data!B$2:B$5001,MATCH(28,Data!$K$2:$K$5001,0)),"") | C35: =IFERROR(INDEX(Data!C$2:C$5001,MATCH(28,Data!$K$2:$K$5001,0)),"") | D35: =IFERROR(INDEX(Data!D$2:D$5001,MATCH(28,Data!$K$2:$K$5001,0)),"") | E35: =IFERROR(INDEX(Data!E$2:E$5001,MATCH(28,Data!$K$2:$K$5001,0)),"") | F35: =IFERROR(INDEX(Data!F$2:F$5001,MATCH(28,Data!$K$2:$K$5001,0)),"") | G35: =IFERROR(INDEX(Data!G$2:G$5001,MATCH(28,Data!$K$2:$K$5001,0)),"") | H35: =IFERROR(INDEX(Data!H$2:H$5001,MATCH(28,Data!$K$2:$K$5001,0)),"")
A36: =IFERROR(INDEX(Data!A$2:A$5001,MATCH(29,Data!$K$2:$K$5001,0)),"") | B36: =IFERROR(INDEX(Data!B$2:B$5001,MATCH(29,Data!$K$2:$K$5001,0)),"") | C36: =IFERROR(INDEX(Data!C$2:C$5001,MATCH(29,Data!$K$2:$K$5001,0)),"") | D36: =IFERROR(INDEX(Data!D$2:D$5001,MATCH(29,Data!$K$2:$K$5001,0)),"") | E36: =IFERROR(INDEX(Data!E$2:E$5001,MATCH(29,Data!$K$2:$K$5001,0)),"") | F36: =IFERROR(INDEX(Data!F$2:F$5001,MATCH(29,Data!$K$2:$K$5001,0)),"") | G36: =IFERROR(INDEX(Data!G$2:G$5001,MATCH(29,Data!$K$2:$K$5001,0)),"") | H36: =IFERROR(INDEX(Data!H$2:H$5001,MATCH(29,Data!$K$2:$K$5001,0)),"")
A37: =IFERROR(INDEX(Data!A$2:A$5001,MATCH(30,Data!$K$2:$K$5001,0)),"") | B37: =IFERROR(INDEX(Data!B$2:B$5001,MATCH(30,Data!$K$2:$K$5001,0)),"") | C37: =IFERROR(INDEX(Data!C$2:C$5001,MATCH(30,Data!$K$2:$K$5001,0)),"") | D37: =IFERROR(INDEX(Data!D$2:D$5001,MATCH(30,Data!$K$2:$K$5001,0)),"") | E37: =IFERROR(INDEX(Data!E$2:E$5001,MATCH(30,Data!$K$2:$K$5001,0)),"") | F37: =IFERROR(INDEX(Data!F$2:F$5001,MATCH(30,Data!$K$2:$K$5001,0)),"") | G37: =IFERROR(INDEX(Data!G$2:G$5001,MATCH(30,Data!$K$2:$K$5001,0)),"") | H37: =IFERROR(INDEX(Data!H$2:H$5001,MATCH(30,Data!$K$2:$K$5001,0)),"")
A38: =IFERROR(INDEX(Data!A$2:A$5001,MATCH(31,Data!$K$2:$K$5001,0)),"") | B38: =IFERROR(INDEX(Data!B$2:B$5001,MATCH(31,Data!$K$2:$K$5001,0)),"") | C38: =IFERROR(INDEX(Data!C$2:C$5001,MATCH(31,Data!$K$2:$K$5001,0)),"") | D38: =IFERROR(INDEX(Data!D$2:D$5001,MATCH(31,Data!$K$2:$K$5001,0)),"") | E38: =IFERROR(INDEX(Data!E$2:E$5001,MATCH(31,Data!$K$2:$K$5001,0)),"") | F38: =IFERROR(INDEX(Data!F$2:F$5001,MATCH(31,Data!$K$2:$K$5001,0)),"") | G38: =IFERROR(INDEX(Data!G$2:G$5001,MATCH(31,Data!$K$2:$K$5001,0)),"") | H38: =IFERROR(INDEX(Data!H$2:H$5001,MATCH(31,Data!$K$2:$K$5001,0)),"")
A39: =IFERROR(INDEX(Data!A$2:A$5001,MATCH(32,Data!$K$2:$K$5001,0)),"") | B39: =IFERROR(INDEX(Data!B$2:B$5001,MATCH(32,Data!$K$2:$K$5001,0)),"") | C39: =IFERROR(INDEX(Data!C$2:C$5001,MATCH(32,Data!$K$2:$K$5001,0)),"") | D39: =IFERROR(INDEX(Data!D$2:D$5001,MATCH(32,Data!$K$2:$K$5001,0)),"") | E39: =IFERROR(INDEX(Data!E$2:E$5001,MATCH(32,Data!$K$2:$K$5001,0)),"") | F39: =IFERROR(INDEX(Data!F$2:F$5001,MATCH(32,Data!$K$2:$K$5001,0)),"") | G39: =IFERROR(INDEX(Data!G$2:G$5001,MATCH(32,Data!$K$2:$K$5001,0)),"") | H39: =IFERROR(INDEX(Data!H$2:H$5001,MATCH(32,Data!$K$2:$K$5001,0)),"")
A40: =IFERROR(INDEX(Data!A$2:A$5001,MATCH(33,Data!$K$2:$K$5001,0)),"") | B40: =IFERROR(INDEX(Data!B$2:B$5001,MATCH(33,Data!$K$2:$K$5001,0)),"") | C40: =IFERROR(INDEX(Data!C$2:C$5001,MATCH(33,Data!$K$2:$K$5001,0)),"") | D40: =IFERROR(INDEX(Data!D$2:D$5001,MATCH(33,Data!$K$2:$K$5001,0)),"") | E40: =IFERROR(INDEX(Data!E$2:E$5001,MATCH(33,Data!$K$2:$K$5001,0)),"") | F40: =IFERROR(INDEX(Data!F$2:F$5001,MATCH(33,Data!$K$2:$K$5001,0)),"") | G40: =IFERROR(INDEX(Data!G$2:G$5001,MATCH(33,Data!$K$2:$K$5001,0)),"") | H40: =IFERROR(INDEX(Data!H$2:H$5001,MATCH(33,Data!$K$2:$K$5001,0)),"")
A41: =IFERROR(INDEX(Data!A$2:A$5001,MATCH(34,Data!$K$2:$K$5001,0)),"") | B41: =IFERROR(INDEX(Data!B$2:B$5001,MATCH(34,Data!$K$2:$K$5001,0)),"") | C41: =IFERROR(INDEX(Data!C$2:C$5001,MATCH(34,Data!$K$2:$K$5001,0)),"") | D41: =IFERROR(INDEX(Data!D$2:D$5001,MATCH(34,Data!$K$2:$K$5001,0)),"") | E41: =IFERROR(INDEX(Data!E$2:E$5001,MATCH(34,Data!$K$2:$K$5001,0)),"") | F41: =IFERROR(INDEX(Data!F$2:F$5001,MATCH(34,Data!$K$2:$K$5001,0)),"") | G41: =IFERROR(INDEX(Data!G$2:G$5001,MATCH(34,Data!$K$2:$K$5001,0)),"") | H41: =IFERROR(INDEX(Data!H$2:H$5001,MATCH(34,Data!$K$2:$K$5001,0)),"")
A42: =IFERROR(INDEX(Data!A$2:A$5001,MATCH(35,Data!$K$2:$K$5001,0)),"") | B42: =IFERROR(INDEX(Data!B$2:B$5001,MATCH(35,Data!$K$2:$K$5001,0)),"") | C42: =IFERROR(INDEX(Data!C$2:C$5001,MATCH(35,Data!$K$2:$K$5001,0)),"") | D42: =IFERROR(INDEX(Data!D$2:D$5001,MATCH(35,Data!$K$2:$K$5001,0)),"") | E42: =IFERROR(INDEX(Data!E$2:E$5001,MATCH(35,Data!$K$2:$K$5001,0)),"") | F42: =IFERROR(INDEX(Data!F$2:F$5001,MATCH(35,Data!$K$2:$K$5001,0)),"") | G42: =IFERROR(INDEX(Data!G$2:G$5001,MATCH(35,Data!$K$2:$K$5001,0)),"") | H42: =IFERROR(INDEX(Data!H$2:H$5001,MATCH(35,Data!$K$2:$K$5001,0)),"")
A43: =IFERROR(INDEX(Data!A$2:A$5001,MATCH(36,Data!$K$2:$K$5001,0)),"") | B43: =IFERROR(INDEX(Data!B$2:B$5001,MATCH(36,Data!$K$2:$K$5001,0)),"") | C43: =IFERROR(INDEX(Data!C$2:C$5001,MATCH(36,Data!$K$2:$K$5001,0)),"") | D43: =IFERROR(INDEX(Data!D$2:D$5001,MATCH(36,Data!$K$2:$K$5001,0)),"") | E43: =IFERROR(INDEX(Data!E$2:E$5001,MATCH(36,Data!$K$2:$K$5001,0)),"") | F43: =IFERROR(INDEX(Data!F$2:F$5001,MATCH(36,Data!$K$2:$K$5001,0)),"") | G43: =IFERROR(INDEX(Data!G$2:G$5001,MATCH(36,Data!$K$2:$K$5001,0)),"") | H43: =IFERROR(INDEX(Data!H$2:H$5001,MATCH(36,Data!$K$2:$K$5001,0)),"")
...

Sheet Data
A1: Barcode | B1: Wood Type | C1: Size | D1: CFT | E1: Lot No. | F1: Date In | G1: Supplier | H1: Rate (Rs) | K1: Match no. | L1: <-- DO NOT DELETE OR SORT THIS COLUMN. The Search tab needs it.
A2: 84729103 | B2: Sheesham | C2: 16 ft x 22 in | D2: 27.47 | E2: LOT-020 | F2: 46148 | G2: Bharuch Traders | H2: 5672 | K2: =IF(Search!$B$3="",0,IF($A2="",N(K1),IF(ISNUMBER(SEARCH(Search!$B$3,$A2&"")),N(K1)+1,N(K1)))) -> 0
A3: 14729556 | B3: Teak | C3: 10 ft x 14 in | D3: 24.93 | E3: LOT-036 | F3: 46166 | G3: Bharuch Traders | H3: 10322 | K3: =IF(Search!$B$3="",0,IF($A3="",N(K2),IF(ISNUMBER(SEARCH(Search!$B$3,$A3&"")),N(K2)+1,N(K2)))) -> 0
A4: 47291880 | B4: Pine | C4: 16 ft x 22 in | D4: 9.53 | E4: LOT-031 | F4: 46252 | G4: Kandla Port Lot | H4: 2142 | K4: =IF(Search!$B$3="",0,IF($A4="",N(K3),IF(ISNUMBER(SEARCH(Search!$B$3,$A4&"")),N(K3)+1,N(K3)))) -> 0
A5: 90847293 | B5: Babul | C5: 16 ft x 22 in | D5: 21.78 | E5: LOT-010 | F5: 46229 | G5: Rajkot Timber Co. | H5: 6569 | K5: =IF(Search!$B$3="",0,IF($A5="",N(K4),IF(ISNUMBER(SEARCH(Search!$B$3,$A5&"")),N(K4)+1,N(K4)))) -> 0
A6: 13315929 | B6: Eucalyptus | C6: 16 ft x 22 in | D6: 4.53 | E6: LOT-040 | F6: 46217 | G6: Gandhidham Depot | H6: 14305 | K6: =IF(Search!$B$3="",0,IF($A6="",N(K5),IF(ISNUMBER(SEARCH(Search!$B$3,$A6&"")),N(K5)+1,N(K5)))) -> 0
A7: 91953710 | B7: Babul | C7: 12 ft x 16 in | D7: 9.67 | E7: LOT-027 | F7: 46201 | G7: Gandhidham Depot | H7: 2488 | K7: =IF(Search!$B$3="",0,IF($A7="",N(K6),IF(ISNUMBER(SEARCH(Search!$B$3,$A7&"")),N(K6)+1,N(K6)))) -> 0
A8: 61401208 | B8: Pine | C8: 10 ft x 14 in | D8: 11.89 | E8: LOT-020 | F8: 46267 | G8: Rajkot Timber Co. | H8: 11079 | K8: =IF(Search!$B$3="",0,IF($A8="",N(K7),IF(ISNUMBER(SEARCH(Search!$B$3,$A8&"")),N(K7)+1,N(K7)))) -> 0
A9: 76156052 | B9: Teak | C9: 8 ft x 12 in | D9: 5.93 | E9: LOT-018 | F9: 46089 | G9: Bharuch Traders | H9: 6259 | K9: =IF(Search!$B$3="",0,IF($A9="",N(K8),IF(ISNUMBER(SEARCH(Search!$B$3,$A9&"")),N(K8)+1,N(K8)))) -> 0
A10: 23218948 | B10: Pine | C10: 12 ft x 18 in | D10: 15.59 | E10: LOT-009 | F10: 46258 | G10: Navsari Sawmill | H10: 1887 | K10: =IF(Search!$B$3="",0,IF($A10="",N(K9),IF(ISNUMBER(SEARCH(Search!$B$3,$A10&"")),N(K9)+1,N(K9)))) -> 0
A11: 50418965 | B11: Eucalyptus | C11: 8 ft x 12 in | D11: 24.17 | E11: LOT-011 | F11: 46179 | G11: Rajkot Timber Co. | H11: 3843 | K11: =IF(Search!$B$3="",0,IF($A11="",N(K10),IF(ISNUMBER(SEARCH(Search!$B$3,$A11&"")),N(K10)+1,N(K10)))) -> 0
A12: 77151849 | B12: Sal | C12: 10 ft x 14 in | D12: 9.54 | E12: LOT-007 | F12: 46232 | G12: Kandla Port Lot | H12: 10825 | K12: =IF(Search!$B$3="",0,IF($A12="",N(K11),IF(ISNUMBER(SEARCH(Search!$B$3,$A12&"")),N(K11)+1,N(K11)))) -> 0
A13: 70595804 | B13: Teak | C13: 14 ft x 20 in | D13: 17.78 | E13: LOT-032 | F13: 46275 | G13: Kandla Port Lot | H13: 9068 | K13: =IF(Search!$B$3="",0,IF($A13="",N(K12),IF(ISNUMBER(SEARCH(Search!$B$3,$A13&"")),N(K12)+1,N(K12)))) -> 0
... A81: 46404990 | B81: Babul | C81: 14 ft x 20 in | D81: 11.48 | E81: LOT-001 | F81: 46185 | G81: Navsari Sawmill | H81: 11159 | K81: =IF(Search!$B$3="",0,IF($A81="",N(K80),IF(ISNUMBER(SEARCH(Search!$B$3,$A81&"")),N(K80)+1,N(K80)))) -> 0
K82: =IF(Search!$B$3="",0,IF($A82="",N(K81),IF(ISNUMBER(SEARCH(Search!$B$3,$A82&"")),N(K81)+1,N(K81)))) -> 0
A83: ^ Paste your real log data above this line, starting in row 2. | K83: =IF(Search!$B$3="",0,IF($A83="",N(K82),IF(ISNUMBER(SEARCH(Search!$B$3,$A83&"")),N(K82)+1,N(K82)))) -> 0
K84: =IF(Search!$B$3="",0,IF($A84="",N(K83),IF(ISNUMBER(SEARCH(Search!$B$3,$A84&"")),N(K83)+1,N(K83)))) -> 0
K85: =IF(Search!$B$3="",0,IF($A85="",N(K84),IF(ISNUMBER(SEARCH(Search!$B$3,$A85&"")),N(K84)+1,N(K84)))) -> 0
K86: =IF(Search!$B$3="",0,IF($A86="",N(K85),IF(ISNUMBER(SEARCH(Search!$B$3,$A86&"")),N(K85)+1,N(K85)))) -> 0
K87: =IF(Search!$B$3="",0,IF($A87="",N(K86),IF(ISNUMBER(SEARCH(Search!$B$3,$A87&"")),N(K86)+1,N(K86)))) -> 0
K88: =IF(Search!$B$3="",0,IF($A88="",N(K87),IF(ISNUMBER(SEARCH(Search!$B$3,$A88&"")),N(K87)+1,N(K87)))) -> 0
K89: =IF(Search!$B$3="",0,IF($A89="",N(K88),IF(ISNUMBER(SEARCH(Search!$B$3,$A89&"")),N(K88)+1,N(K88)))) -> 0
K90: =IF(Search!$B$3="",0,IF($A90="",N(K89),IF(ISNUMBER(SEARCH(Search!$B$3,$A90&"")),N(K89)+1,N(K89)))) -> 0
K91: =IF(Search!$B$3="",0,IF($A91="",N(K90),IF(ISNUMBER(SEARCH(Search!$B$3,$A91&"")),N(K90)+1,N(K90)))) -> 0
K92: =IF(Search!$B$3="",0,IF($A92="",N(K91),IF(ISNUMBER(SEARCH(Search!$B$3,$A92&"")),N(K91)+1,N(K91)))) -> 0
K93: =IF(Search!$B$3="",0,IF($A93="",N(K92),IF(ISNUMBER(SEARCH(Search!$B$3,$A93&"")),N(K92)+1,N(K92)))) -> 0
K94: =IF(Search!$B$3="",0,IF($A94="",N(K93),IF(ISNUMBER(SEARCH(Search!$B$3,$A94&"")),N(K93)+1,N(K93)))) -> 0
K95: =IF(Search!$B$3="",0,IF($A95="",N(K94),IF(ISNUMBER(SEARCH(Search!$B$3,$A95&"")),N(K94)+1,N(K94)))) -> 0
... K5001: =IF(Search!$B$3="",0,IF($A5001="",N(K5000),IF(ISNUMBER(SEARCH(Search!$B$3,$A5001&"")),N(K5000)+1,N(K5000)))) -> 0

Sheet Read me
B2: How this file works
B4: There are two tabs that matter, at the bottom of the window:
B5: • Data — every log, one per row. This is the sheet the accountant keeps filling in.
B6: • Search — the yellow box. Type a barcode, matching logs appear underneath it.
B8: Nothing is ever typed on the Search tab except the yellow box. It reads the Data tab automatically.
B10: Putting your real data in
B12: 1. Open your existing barcode file and the Data tab of this file, side by side.
B13: 2. In your old file, select your data WITHOUT the header row, and copy it.
B14: 3. Click cell A2 on the Data tab here, then Paste Special > Values only.
B15: 4. Delete the sample rows that are still left below your pasted data.
B16: 5. If your columns are in a different order, drag the headers in row 1 to match yours.
B18: Never delete, sort or drag column K on the Data tab. It is the machinery the search runs on. If it is gone, the Search tab shows nothing.
... B43: Built for Kushal Timbers. Works in Excel 2007 and newer, in WPS Office, and in Google Sheets.
